2019-10-08 16:50:58,450 [Dummy-1: 123145397166080]/Users/chengyinliu/anaconda3/lib/python3.7/site-packages/django/db/backends/utils.py:execute:111 DEBUG - (0.002) SELECT @@SQL_AUTO_IS_NULL; args=None
2019-10-08 16:50:58,450 [Dummy-1: 123145397166080]/Users/chengyinliu/anaconda3/lib/python3.7/site-packages/django/db/backends/utils.py:execute:111 DEBUG - (0.000) SET SESSION TRANSACTION ISOLATION LEVEL READ COMMITTED; args=None
2019-10-08 16:50:58,452 [Dummy-1: 123145397166080]/Users/chengyinliu/anaconda3/lib/python3.7/site-packages/django/db/backends/utils.py:execute:111 DEBUG - (0.001) SELECT VERSION(); args=None
2019-10-08 16:50:58,484 [Dummy-1: 123145397166080]/Users/chengyinliu/anaconda3/lib/python3.7/site-packages/django/db/backends/utils.py:execute:111 DEBUG - (0.000) SET SESSION TRANSACTION ISOLATION LEVEL READ COMMITTED; args=None
2019-10-08 16:50:58,498 [Dummy-1: 123145397166080]/Users/chengyinliu/anaconda3/lib/python3.7/site-packages/django/db/backends/utils.py:execute:111 DEBUG - (0.014) SHOW FULL TABLES; args=None
2019-10-08 16:50:58,511 [Dummy-1: 123145397166080]/Users/chengyinliu/anaconda3/lib/python3.7/site-packages/django/db/backends/utils.py:execute:111 DEBUG - (0.011) SELECT `django_migrations`.`app`, `django_migrations`.`name` FROM `django_migrations`; args=()
2019-10-08 16:50:58,517 [Dummy-1: 123145397166080]/Users/chengyinliu/WeChatProjects/backend/module/middleware.py:__init__:14 INFO - Build StatisticsMiddleware.
2019-10-08 16:52:20,645 [Thread-2: 123145402421248]/Users/chengyinliu/anaconda3/lib/python3.7/site-packages/django/template/base.py:_resolve_lookup:878 DEBUG - Exception while resolving variable 'name' in template 'unknown'.
Traceback (most recent call last):
  File "/Users/chengyinliu/anaconda3/lib/python3.7/site-packages/django/core/handlers/exception.py", line 35, in inner
    response = get_response(request)
  File "/Users/chengyinliu/anaconda3/lib/python3.7/site-packages/django/core/handlers/base.py", line 113, in _get_response
    resolver_match = resolver.resolve(request.path_info)
  File "/Users/chengyinliu/anaconda3/lib/python3.7/site-packages/django/urls/resolvers.py", line 527, in resolve
    raise Resolver404({'tried': tried, 'path': new_path})
django.urls.exceptions.Resolver404: {'tried': [[<URLResolver <URLPattern list> (admin:admin) 'admin/'>], [<URLResolver <module 'backend.version_1_0' from '/Users/chengyinliu/WeChatProjects/backend/backend/version_1_0.py'> (None:None) 'api/v1.0/'>]], 'path': 'all/rss/'}

During handling of the above exception, another exception occurred:

Traceback (most recent call last):
  File "/Users/chengyinliu/anaconda3/lib/python3.7/site-packages/django/template/base.py", line 835, in _resolve_lookup
    current = current[bit]
TypeError: 'URLResolver' object is not subscriptable

During handling of the above exception, another exception occurred:

Traceback (most recent call last):
  File "/Users/chengyinliu/anaconda3/lib/python3.7/site-packages/django/template/base.py", line 843, in _resolve_lookup
    current = getattr(current, bit)
AttributeError: 'URLResolver' object has no attribute 'name'

During handling of the above exception, another exception occurred:

Traceback (most recent call last):
  File "/Users/chengyinliu/anaconda3/lib/python3.7/site-packages/django/template/base.py", line 849, in _resolve_lookup
    current = current[int(bit)]
ValueError: invalid literal for int() with base 10: 'name'

During handling of the above exception, another exception occurred:

Traceback (most recent call last):
  File "/Users/chengyinliu/anaconda3/lib/python3.7/site-packages/django/template/base.py", line 856, in _resolve_lookup
    (bit, current))  # missing attribute
django.template.base.VariableDoesNotExist: Failed lookup for key [name] in <URLResolver <URLPattern list> (admin:admin) 'admin/'>
2019-10-08 16:52:20,650 [Thread-2: 123145402421248]/Users/chengyinliu/anaconda3/lib/python3.7/site-packages/django/template/base.py:_resolve_lookup:878 DEBUG - Exception while resolving variable 'name' in template 'unknown'.
Traceback (most recent call last):
  File "/Users/chengyinliu/anaconda3/lib/python3.7/site-packages/django/core/handlers/exception.py", line 35, in inner
    response = get_response(request)
  File "/Users/chengyinliu/anaconda3/lib/python3.7/site-packages/django/core/handlers/base.py", line 113, in _get_response
    resolver_match = resolver.resolve(request.path_info)
  File "/Users/chengyinliu/anaconda3/lib/python3.7/site-packages/django/urls/resolvers.py", line 527, in resolve
    raise Resolver404({'tried': tried, 'path': new_path})
django.urls.exceptions.Resolver404: {'tried': [[<URLResolver <URLPattern list> (admin:admin) 'admin/'>], [<URLResolver <module 'backend.version_1_0' from '/Users/chengyinliu/WeChatProjects/backend/backend/version_1_0.py'> (None:None) 'api/v1.0/'>]], 'path': 'all/rss/'}

During handling of the above exception, another exception occurred:

Traceback (most recent call last):
  File "/Users/chengyinliu/anaconda3/lib/python3.7/site-packages/django/template/base.py", line 835, in _resolve_lookup
    current = current[bit]
TypeError: 'URLResolver' object is not subscriptable

During handling of the above exception, another exception occurred:

Traceback (most recent call last):
  File "/Users/chengyinliu/anaconda3/lib/python3.7/site-packages/django/template/base.py", line 843, in _resolve_lookup
    current = getattr(current, bit)
AttributeError: 'URLResolver' object has no attribute 'name'

During handling of the above exception, another exception occurred:

Traceback (most recent call last):
  File "/Users/chengyinliu/anaconda3/lib/python3.7/site-packages/django/template/base.py", line 849, in _resolve_lookup
    current = current[int(bit)]
ValueError: invalid literal for int() with base 10: 'name'

During handling of the above exception, another exception occurred:

Traceback (most recent call last):
  File "/Users/chengyinliu/anaconda3/lib/python3.7/site-packages/django/template/base.py", line 856, in _resolve_lookup
    (bit, current))  # missing attribute
django.template.base.VariableDoesNotExist: Failed lookup for key [name] in <URLResolver <module 'backend.version_1_0' from '/Users/chengyinliu/WeChatProjects/backend/backend/version_1_0.py'> (None:None) 'api/v1.0/'>
2019-10-08 16:52:20,651 [Thread-2: 123145402421248]/Users/chengyinliu/anaconda3/lib/python3.7/site-packages/django/core/handlers/base.py:get_response:93 WARNING - Not Found: /all/rss/
2019-10-08 16:52:20,652 [Thread-2: 123145402421248]/Users/chengyinliu/anaconda3/lib/python3.7/site-packages/django/core/servers/basehttp.py:log_message:124 WARNING - "GET /all/rss/ HTTP/1.1" 404 2073
2019-10-08 16:55:18,289 [Thread-3: 123145402421248]/Users/chengyinliu/anaconda3/lib/python3.7/site-packages/django/core/servers/basehttp.py:log_message:124 INFO - "GET /api/v1.0/service/test HTTP/1.1" 200 11
2019-10-08 16:55:18,292 [Thread-4: 123145402421248]/Users/chengyinliu/anaconda3/lib/python3.7/site-packages/django/core/servers/basehttp.py:log_message:124 INFO - "GET /api/v1.0/service/image/list HTTP/1.1" 200 143
2019-10-08 16:55:19,299 [Thread-5: 123145402421248]/Users/chengyinliu/anaconda3/lib/python3.7/site-packages/django/core/servers/basehttp.py:log_message:124 INFO - "GET /api/v1.0/service/test HTTP/1.1" 200 11
2019-10-08 16:55:19,304 [Thread-6: 123145402421248]/Users/chengyinliu/anaconda3/lib/python3.7/site-packages/django/core/servers/basehttp.py:log_message:124 INFO - "GET /api/v1.0/service/image/list HTTP/1.1" 200 143
2019-10-08 16:55:20,317 [Thread-7: 123145402421248]/Users/chengyinliu/anaconda3/lib/python3.7/site-packages/django/core/servers/basehttp.py:log_message:124 INFO - "GET /api/v1.0/service/test HTTP/1.1" 200 11
2019-10-08 16:55:20,322 [Thread-8: 123145402421248]/Users/chengyinliu/anaconda3/lib/python3.7/site-packages/django/core/servers/basehttp.py:log_message:124 INFO - "GET /api/v1.0/service/image/list HTTP/1.1" 200 143
2019-10-08 16:55:21,331 [Thread-9: 123145402421248]/Users/chengyinliu/anaconda3/lib/python3.7/site-packages/django/core/servers/basehttp.py:log_message:124 INFO - "GET /api/v1.0/service/test HTTP/1.1" 200 11
2019-10-08 16:55:21,336 [Thread-10: 123145402421248]/Users/chengyinliu/anaconda3/lib/python3.7/site-packages/django/core/servers/basehttp.py:log_message:124 INFO - "GET /api/v1.0/service/image/list HTTP/1.1" 200 143
2019-10-08 16:55:22,348 [Thread-11: 123145402421248]/Users/chengyinliu/anaconda3/lib/python3.7/site-packages/django/core/servers/basehttp.py:log_message:124 INFO - "GET /api/v1.0/service/test HTTP/1.1" 200 11
2019-10-08 16:55:22,354 [Thread-12: 123145402421248]/Users/chengyinliu/anaconda3/lib/python3.7/site-packages/django/core/servers/basehttp.py:log_message:124 INFO - "GET /api/v1.0/service/image/list HTTP/1.1" 200 143
2019-10-08 16:55:23,362 [Thread-13: 123145402421248]/Users/chengyinliu/anaconda3/lib/python3.7/site-packages/django/core/servers/basehttp.py:log_message:124 INFO - "GET /api/v1.0/service/test HTTP/1.1" 200 11
2019-10-08 16:55:23,369 [Thread-14: 123145402421248]/Users/chengyinliu/anaconda3/lib/python3.7/site-packages/django/core/servers/basehttp.py:log_message:124 INFO - "GET /api/v1.0/service/image/list HTTP/1.1" 200 143
2019-10-08 16:55:24,376 [Thread-15: 123145402421248]/Users/chengyinliu/anaconda3/lib/python3.7/site-packages/django/core/servers/basehttp.py:log_message:124 INFO - "GET /api/v1.0/service/test HTTP/1.1" 200 11
2019-10-08 16:55:24,379 [Thread-16: 123145402421248]/Users/chengyinliu/anaconda3/lib/python3.7/site-packages/django/core/servers/basehttp.py:log_message:124 INFO - "GET /api/v1.0/service/image/list HTTP/1.1" 200 143
2019-10-08 16:55:25,387 [Thread-17: 123145402421248]/Users/chengyinliu/anaconda3/lib/python3.7/site-packages/django/core/servers/basehttp.py:log_message:124 INFO - "GET /api/v1.0/service/test HTTP/1.1" 200 11
2019-10-08 16:55:25,392 [Thread-18: 123145402421248]/Users/chengyinliu/anaconda3/lib/python3.7/site-packages/django/core/servers/basehttp.py:log_message:124 INFO - "GET /api/v1.0/service/image/list HTTP/1.1" 200 143
2019-10-08 16:55:26,396 [Thread-19: 123145402421248]/Users/chengyinliu/anaconda3/lib/python3.7/site-packages/django/core/servers/basehttp.py:log_message:124 INFO - "GET /api/v1.0/service/test HTTP/1.1" 200 11
2019-10-08 16:55:26,400 [Thread-20: 123145402421248]/Users/chengyinliu/anaconda3/lib/python3.7/site-packages/django/core/servers/basehttp.py:log_message:124 INFO - "GET /api/v1.0/service/image/list HTTP/1.1" 200 143
2019-10-08 16:55:27,412 [Thread-21: 123145402421248]/Users/chengyinliu/anaconda3/lib/python3.7/site-packages/django/core/servers/basehttp.py:log_message:124 INFO - "GET /api/v1.0/service/test HTTP/1.1" 200 11
2019-10-08 16:55:27,420 [Thread-22: 123145402421248]/Users/chengyinliu/anaconda3/lib/python3.7/site-packages/django/core/servers/basehttp.py:log_message:124 INFO - "GET /api/v1.0/service/image/list HTTP/1.1" 200 143
2019-10-08 16:55:28,427 [Thread-23: 123145402421248]/Users/chengyinliu/anaconda3/lib/python3.7/site-packages/django/core/servers/basehttp.py:log_message:124 INFO - "GET /api/v1.0/service/test HTTP/1.1" 200 11
2019-10-08 16:55:28,434 [Thread-24: 123145402421248]/Users/chengyinliu/anaconda3/lib/python3.7/site-packages/django/core/servers/basehttp.py:log_message:124 INFO - "GET /api/v1.0/service/image/list HTTP/1.1" 200 143
2019-10-08 16:55:29,444 [Thread-25: 123145402421248]/Users/chengyinliu/anaconda3/lib/python3.7/site-packages/django/core/servers/basehttp.py:log_message:124 INFO - "GET /api/v1.0/service/test HTTP/1.1" 200 11
2019-10-08 16:55:29,449 [Thread-26: 123145402421248]/Users/chengyinliu/anaconda3/lib/python3.7/site-packages/django/core/servers/basehttp.py:log_message:124 INFO - "GET /api/v1.0/service/image/list HTTP/1.1" 200 143
2019-10-08 16:55:30,461 [Thread-27: 123145402421248]/Users/chengyinliu/anaconda3/lib/python3.7/site-packages/django/core/servers/basehttp.py:log_message:124 INFO - "GET /api/v1.0/service/test HTTP/1.1" 200 11
2019-10-08 16:55:30,467 [Thread-28: 123145402421248]/Users/chengyinliu/anaconda3/lib/python3.7/site-packages/django/core/servers/basehttp.py:log_message:124 INFO - "GET /api/v1.0/service/image/list HTTP/1.1" 200 143
2019-10-08 16:55:31,478 [Thread-29: 123145402421248]/Users/chengyinliu/anaconda3/lib/python3.7/site-packages/django/core/servers/basehttp.py:log_message:124 INFO - "GET /api/v1.0/service/test HTTP/1.1" 200 11
2019-10-08 16:55:31,485 [Thread-30: 123145402421248]/Users/chengyinliu/anaconda3/lib/python3.7/site-packages/django/core/servers/basehttp.py:log_message:124 INFO - "GET /api/v1.0/service/image/list HTTP/1.1" 200 143
2019-10-08 16:55:32,497 [Thread-31: 123145402421248]/Users/chengyinliu/anaconda3/lib/python3.7/site-packages/django/core/servers/basehttp.py:log_message:124 INFO - "GET /api/v1.0/service/test HTTP/1.1" 200 11
2019-10-08 16:55:32,502 [Thread-32: 123145402421248]/Users/chengyinliu/anaconda3/lib/python3.7/site-packages/django/core/servers/basehttp.py:log_message:124 INFO - "GET /api/v1.0/service/image/list HTTP/1.1" 200 143
2019-10-08 16:55:33,510 [Thread-33: 123145402421248]/Users/chengyinliu/anaconda3/lib/python3.7/site-packages/django/core/servers/basehttp.py:log_message:124 INFO - "GET /api/v1.0/service/test HTTP/1.1" 200 11
2019-10-08 16:55:33,515 [Thread-34: 123145402421248]/Users/chengyinliu/anaconda3/lib/python3.7/site-packages/django/core/servers/basehttp.py:log_message:124 INFO - "GET /api/v1.0/service/image/list HTTP/1.1" 200 143
2019-10-08 16:55:34,524 [Thread-35: 123145402421248]/Users/chengyinliu/anaconda3/lib/python3.7/site-packages/django/core/servers/basehttp.py:log_message:124 INFO - "GET /api/v1.0/service/test HTTP/1.1" 200 11
2019-10-08 16:55:34,530 [Thread-36: 123145402421248]/Users/chengyinliu/anaconda3/lib/python3.7/site-packages/django/core/servers/basehttp.py:log_message:124 INFO - "GET /api/v1.0/service/image/list HTTP/1.1" 200 143
2019-10-08 16:55:35,543 [Thread-37: 123145402421248]/Users/chengyinliu/anaconda3/lib/python3.7/site-packages/django/core/servers/basehttp.py:log_message:124 INFO - "GET /api/v1.0/service/test HTTP/1.1" 200 11
2019-10-08 16:55:35,548 [Thread-38: 123145402421248]/Users/chengyinliu/anaconda3/lib/python3.7/site-packages/django/core/servers/basehttp.py:log_message:124 INFO - "GET /api/v1.0/service/image/list HTTP/1.1" 200 143
2019-10-08 16:55:36,558 [Thread-39: 123145402421248]/Users/chengyinliu/anaconda3/lib/python3.7/site-packages/django/core/servers/basehttp.py:log_message:124 INFO - "GET /api/v1.0/service/test HTTP/1.1" 200 11
2019-10-08 16:55:36,563 [Thread-40: 123145402421248]/Users/chengyinliu/anaconda3/lib/python3.7/site-packages/django/core/servers/basehttp.py:log_message:124 INFO - "GET /api/v1.0/service/image/list HTTP/1.1" 200 143
2019-10-08 16:55:37,572 [Thread-41: 123145402421248]/Users/chengyinliu/anaconda3/lib/python3.7/site-packages/django/core/servers/basehttp.py:log_message:124 INFO - "GET /api/v1.0/service/test HTTP/1.1" 200 11
2019-10-08 16:55:37,578 [Thread-42: 123145402421248]/Users/chengyinliu/anaconda3/lib/python3.7/site-packages/django/core/servers/basehttp.py:log_message:124 INFO - "GET /api/v1.0/service/image/list HTTP/1.1" 200 143
2019-10-08 16:55:38,585 [Thread-43: 123145402421248]/Users/chengyinliu/anaconda3/lib/python3.7/site-packages/django/core/servers/basehttp.py:log_message:124 INFO - "GET /api/v1.0/service/test HTTP/1.1" 200 11
2019-10-08 16:55:38,590 [Thread-44: 123145402421248]/Users/chengyinliu/anaconda3/lib/python3.7/site-packages/django/core/servers/basehttp.py:log_message:124 INFO - "GET /api/v1.0/service/image/list HTTP/1.1" 200 143
2019-10-08 16:55:39,596 [Thread-45: 123145402421248]/Users/chengyinliu/anaconda3/lib/python3.7/site-packages/django/core/servers/basehttp.py:log_message:124 INFO - "GET /api/v1.0/service/test HTTP/1.1" 200 11
2019-10-08 16:55:39,601 [Thread-46: 123145402421248]/Users/chengyinliu/anaconda3/lib/python3.7/site-packages/django/core/servers/basehttp.py:log_message:124 INFO - "GET /api/v1.0/service/image/list HTTP/1.1" 200 143
2019-10-08 16:55:40,610 [Thread-47: 123145402421248]/Users/chengyinliu/anaconda3/lib/python3.7/site-packages/django/core/servers/basehttp.py:log_message:124 INFO - "GET /api/v1.0/service/test HTTP/1.1" 200 11
2019-10-08 16:55:40,617 [Thread-48: 123145402421248]/Users/chengyinliu/anaconda3/lib/python3.7/site-packages/django/core/servers/basehttp.py:log_message:124 INFO - "GET /api/v1.0/service/image/list HTTP/1.1" 200 143
2019-10-08 16:55:41,624 [Thread-49: 123145402421248]/Users/chengyinliu/anaconda3/lib/python3.7/site-packages/django/core/servers/basehttp.py:log_message:124 INFO - "GET /api/v1.0/service/test HTTP/1.1" 200 11
2019-10-08 16:55:41,629 [Thread-50: 123145402421248]/Users/chengyinliu/anaconda3/lib/python3.7/site-packages/django/core/servers/basehttp.py:log_message:124 INFO - "GET /api/v1.0/service/image/list HTTP/1.1" 200 143
2019-10-08 16:55:42,638 [Thread-51: 123145402421248]/Users/chengyinliu/anaconda3/lib/python3.7/site-packages/django/core/servers/basehttp.py:log_message:124 INFO - "GET /api/v1.0/service/test HTTP/1.1" 200 11
2019-10-08 16:55:42,645 [Thread-52: 123145402421248]/Users/chengyinliu/anaconda3/lib/python3.7/site-packages/django/core/servers/basehttp.py:log_message:124 INFO - "GET /api/v1.0/service/image/list HTTP/1.1" 200 143
2019-10-08 16:57:11,672 [Dummy-1: 123145320398848]/Users/chengyinliu/anaconda3/lib/python3.7/site-packages/django/db/backends/utils.py:execute:111 DEBUG - (0.000) SELECT @@SQL_AUTO_IS_NULL; args=None
2019-10-08 16:57:11,672 [Dummy-1: 123145320398848]/Users/chengyinliu/anaconda3/lib/python3.7/site-packages/django/db/backends/utils.py:execute:111 DEBUG - (0.000) SET SESSION TRANSACTION ISOLATION LEVEL READ COMMITTED; args=None
2019-10-08 16:57:11,673 [Dummy-1: 123145320398848]/Users/chengyinliu/anaconda3/lib/python3.7/site-packages/django/db/backends/utils.py:execute:111 DEBUG - (0.000) SELECT VERSION(); args=None
2019-10-08 16:57:11,690 [Dummy-1: 123145320398848]/Users/chengyinliu/anaconda3/lib/python3.7/site-packages/django/db/backends/utils.py:execute:111 DEBUG - (0.000) SET SESSION TRANSACTION ISOLATION LEVEL READ COMMITTED; args=None
2019-10-08 16:57:11,693 [Dummy-1: 123145320398848]/Users/chengyinliu/anaconda3/lib/python3.7/site-packages/django/db/backends/utils.py:execute:111 DEBUG - (0.003) SHOW FULL TABLES; args=None
2019-10-08 16:57:11,696 [Dummy-1: 123145320398848]/Users/chengyinliu/anaconda3/lib/python3.7/site-packages/django/db/backends/utils.py:execute:111 DEBUG - (0.001) SELECT `django_migrations`.`app`, `django_migrations`.`name` FROM `django_migrations`; args=()
2019-10-08 16:57:11,699 [Dummy-1: 123145320398848]/Users/chengyinliu/WeChatProjects/backend/module/middleware.py:__init__:14 INFO - Build StatisticsMiddleware.
2019-10-08 16:58:06,594 [Dummy-1: 123145455476736]/Users/chengyinliu/anaconda3/lib/python3.7/site-packages/django/db/backends/utils.py:execute:111 DEBUG - (0.000) SELECT @@SQL_AUTO_IS_NULL; args=None
2019-10-08 16:58:06,594 [Dummy-1: 123145455476736]/Users/chengyinliu/anaconda3/lib/python3.7/site-packages/django/db/backends/utils.py:execute:111 DEBUG - (0.000) SET SESSION TRANSACTION ISOLATION LEVEL READ COMMITTED; args=None
2019-10-08 16:58:06,594 [Dummy-1: 123145455476736]/Users/chengyinliu/anaconda3/lib/python3.7/site-packages/django/db/backends/utils.py:execute:111 DEBUG - (0.000) SELECT VERSION(); args=None
2019-10-08 16:58:06,611 [Dummy-1: 123145455476736]/Users/chengyinliu/anaconda3/lib/python3.7/site-packages/django/db/backends/utils.py:execute:111 DEBUG - (0.000) SET SESSION TRANSACTION ISOLATION LEVEL READ COMMITTED; args=None
2019-10-08 16:58:06,612 [Dummy-1: 123145455476736]/Users/chengyinliu/anaconda3/lib/python3.7/site-packages/django/db/backends/utils.py:execute:111 DEBUG - (0.001) SHOW FULL TABLES; args=None
2019-10-08 16:58:06,614 [Dummy-1: 123145455476736]/Users/chengyinliu/anaconda3/lib/python3.7/site-packages/django/db/backends/utils.py:execute:111 DEBUG - (0.001) SELECT `django_migrations`.`app`, `django_migrations`.`name` FROM `django_migrations`; args=()
2019-10-08 16:58:06,617 [Dummy-1: 123145455476736]/Users/chengyinliu/WeChatProjects/backend/module/middleware.py:__init__:14 INFO - Build StatisticsMiddleware.
2019-10-08 16:58:21,488 [Dummy-1: 123145412255744]/Users/chengyinliu/anaconda3/lib/python3.7/site-packages/django/db/backends/utils.py:execute:111 DEBUG - (0.000) SELECT @@SQL_AUTO_IS_NULL; args=None
2019-10-08 16:58:21,489 [Dummy-1: 123145412255744]/Users/chengyinliu/anaconda3/lib/python3.7/site-packages/django/db/backends/utils.py:execute:111 DEBUG - (0.000) SET SESSION TRANSACTION ISOLATION LEVEL READ COMMITTED; args=None
2019-10-08 16:58:21,489 [Dummy-1: 123145412255744]/Users/chengyinliu/anaconda3/lib/python3.7/site-packages/django/db/backends/utils.py:execute:111 DEBUG - (0.000) SELECT VERSION(); args=None
2019-10-08 16:58:21,505 [Dummy-1: 123145412255744]/Users/chengyinliu/anaconda3/lib/python3.7/site-packages/django/db/backends/utils.py:execute:111 DEBUG - (0.000) SET SESSION TRANSACTION ISOLATION LEVEL READ COMMITTED; args=None
2019-10-08 16:58:21,506 [Dummy-1: 123145412255744]/Users/chengyinliu/anaconda3/lib/python3.7/site-packages/django/db/backends/utils.py:execute:111 DEBUG - (0.001) SHOW FULL TABLES; args=None
2019-10-08 16:58:21,508 [Dummy-1: 123145412255744]/Users/chengyinliu/anaconda3/lib/python3.7/site-packages/django/db/backends/utils.py:execute:111 DEBUG - (0.001) SELECT `django_migrations`.`app`, `django_migrations`.`name` FROM `django_migrations`; args=()
2019-10-08 16:58:21,512 [Dummy-1: 123145412255744]/Users/chengyinliu/WeChatProjects/backend/module/middleware.py:__init__:14 INFO - Build StatisticsMiddleware.
2019-10-08 16:59:58,576 [Dummy-1: 123145333043200]/Users/chengyinliu/anaconda3/lib/python3.7/site-packages/django/db/backends/utils.py:execute:111 DEBUG - (0.000) SELECT @@SQL_AUTO_IS_NULL; args=None
2019-10-08 16:59:58,576 [Dummy-1: 123145333043200]/Users/chengyinliu/anaconda3/lib/python3.7/site-packages/django/db/backends/utils.py:execute:111 DEBUG - (0.000) SET SESSION TRANSACTION ISOLATION LEVEL READ COMMITTED; args=None
2019-10-08 16:59:58,577 [Dummy-1: 123145333043200]/Users/chengyinliu/anaconda3/lib/python3.7/site-packages/django/db/backends/utils.py:execute:111 DEBUG - (0.000) SELECT VERSION(); args=None
2019-10-08 16:59:58,595 [Dummy-1: 123145333043200]/Users/chengyinliu/anaconda3/lib/python3.7/site-packages/django/db/backends/utils.py:execute:111 DEBUG - (0.000) SET SESSION TRANSACTION ISOLATION LEVEL READ COMMITTED; args=None
2019-10-08 16:59:58,596 [Dummy-1: 123145333043200]/Users/chengyinliu/anaconda3/lib/python3.7/site-packages/django/db/backends/utils.py:execute:111 DEBUG - (0.001) SHOW FULL TABLES; args=None
2019-10-08 16:59:58,598 [Dummy-1: 123145333043200]/Users/chengyinliu/anaconda3/lib/python3.7/site-packages/django/db/backends/utils.py:execute:111 DEBUG - (0.001) SELECT `django_migrations`.`app`, `django_migrations`.`name` FROM `django_migrations`; args=()
2019-10-08 16:59:58,602 [Dummy-1: 123145333043200]/Users/chengyinliu/WeChatProjects/backend/module/middleware.py:__init__:14 INFO - Build StatisticsMiddleware.
2019-10-08 17:00:20,635 [Dummy-1: 123145348808704]/Users/chengyinliu/anaconda3/lib/python3.7/site-packages/django/db/backends/utils.py:execute:111 DEBUG - (0.000) SELECT @@SQL_AUTO_IS_NULL; args=None
2019-10-08 17:00:20,635 [Dummy-1: 123145348808704]/Users/chengyinliu/anaconda3/lib/python3.7/site-packages/django/db/backends/utils.py:execute:111 DEBUG - (0.000) SET SESSION TRANSACTION ISOLATION LEVEL READ COMMITTED; args=None
2019-10-08 17:00:20,635 [Dummy-1: 123145348808704]/Users/chengyinliu/anaconda3/lib/python3.7/site-packages/django/db/backends/utils.py:execute:111 DEBUG - (0.000) SELECT VERSION(); args=None
2019-10-08 17:00:20,653 [Dummy-1: 123145348808704]/Users/chengyinliu/anaconda3/lib/python3.7/site-packages/django/db/backends/utils.py:execute:111 DEBUG - (0.000) SET SESSION TRANSACTION ISOLATION LEVEL READ COMMITTED; args=None
2019-10-08 17:00:20,654 [Dummy-1: 123145348808704]/Users/chengyinliu/anaconda3/lib/python3.7/site-packages/django/db/backends/utils.py:execute:111 DEBUG - (0.001) SHOW FULL TABLES; args=None
2019-10-08 17:00:20,656 [Dummy-1: 123145348808704]/Users/chengyinliu/anaconda3/lib/python3.7/site-packages/django/db/backends/utils.py:execute:111 DEBUG - (0.001) SELECT `django_migrations`.`app`, `django_migrations`.`name` FROM `django_migrations`; args=()
2019-10-08 17:00:20,660 [Dummy-1: 123145348808704]/Users/chengyinliu/WeChatProjects/backend/module/middleware.py:__init__:14 INFO - Build StatisticsMiddleware.
2019-10-08 17:00:26,272 [Dummy-1: 123145525157888]/Users/chengyinliu/anaconda3/lib/python3.7/site-packages/django/db/backends/utils.py:execute:111 DEBUG - (0.000) SELECT @@SQL_AUTO_IS_NULL; args=None
2019-10-08 17:00:26,273 [Dummy-1: 123145525157888]/Users/chengyinliu/anaconda3/lib/python3.7/site-packages/django/db/backends/utils.py:execute:111 DEBUG - (0.000) SET SESSION TRANSACTION ISOLATION LEVEL READ COMMITTED; args=None
2019-10-08 17:00:26,273 [Dummy-1: 123145525157888]/Users/chengyinliu/anaconda3/lib/python3.7/site-packages/django/db/backends/utils.py:execute:111 DEBUG - (0.000) SELECT VERSION(); args=None
2019-10-08 17:00:26,290 [Dummy-1: 123145525157888]/Users/chengyinliu/anaconda3/lib/python3.7/site-packages/django/db/backends/utils.py:execute:111 DEBUG - (0.000) SET SESSION TRANSACTION ISOLATION LEVEL READ COMMITTED; args=None
2019-10-08 17:00:26,291 [Dummy-1: 123145525157888]/Users/chengyinliu/anaconda3/lib/python3.7/site-packages/django/db/backends/utils.py:execute:111 DEBUG - (0.001) SHOW FULL TABLES; args=None
2019-10-08 17:00:26,293 [Dummy-1: 123145525157888]/Users/chengyinliu/anaconda3/lib/python3.7/site-packages/django/db/backends/utils.py:execute:111 DEBUG - (0.001) SELECT `django_migrations`.`app`, `django_migrations`.`name` FROM `django_migrations`; args=()
2019-10-08 17:00:26,297 [Dummy-1: 123145525157888]/Users/chengyinliu/WeChatProjects/backend/module/middleware.py:__init__:14 INFO - Build StatisticsMiddleware.
2019-10-08 17:00:43,183 [Dummy-1: 123145407012864]/Users/chengyinliu/anaconda3/lib/python3.7/site-packages/django/db/backends/utils.py:execute:111 DEBUG - (0.000) SELECT @@SQL_AUTO_IS_NULL; args=None
2019-10-08 17:00:43,183 [Dummy-1: 123145407012864]/Users/chengyinliu/anaconda3/lib/python3.7/site-packages/django/db/backends/utils.py:execute:111 DEBUG - (0.000) SET SESSION TRANSACTION ISOLATION LEVEL READ COMMITTED; args=None
2019-10-08 17:00:43,183 [Dummy-1: 123145407012864]/Users/chengyinliu/anaconda3/lib/python3.7/site-packages/django/db/backends/utils.py:execute:111 DEBUG - (0.000) SELECT VERSION(); args=None
2019-10-08 17:00:43,200 [Dummy-1: 123145407012864]/Users/chengyinliu/anaconda3/lib/python3.7/site-packages/django/db/backends/utils.py:execute:111 DEBUG - (0.000) SET SESSION TRANSACTION ISOLATION LEVEL READ COMMITTED; args=None
2019-10-08 17:00:43,201 [Dummy-1: 123145407012864]/Users/chengyinliu/anaconda3/lib/python3.7/site-packages/django/db/backends/utils.py:execute:111 DEBUG - (0.001) SHOW FULL TABLES; args=None
2019-10-08 17:00:43,203 [Dummy-1: 123145407012864]/Users/chengyinliu/anaconda3/lib/python3.7/site-packages/django/db/backends/utils.py:execute:111 DEBUG - (0.001) SELECT `django_migrations`.`app`, `django_migrations`.`name` FROM `django_migrations`; args=()
2019-10-08 17:00:43,207 [Dummy-1: 123145407012864]/Users/chengyinliu/WeChatProjects/backend/module/middleware.py:__init__:14 INFO - Build StatisticsMiddleware.
2019-10-08 17:02:20,675 [Thread-2: 123145412268032]/Users/chengyinliu/anaconda3/lib/python3.7/site-packages/django/template/base.py:_resolve_lookup:878 DEBUG - Exception while resolving variable 'name' in template 'unknown'.
Traceback (most recent call last):
  File "/Users/chengyinliu/anaconda3/lib/python3.7/site-packages/django/core/handlers/exception.py", line 35, in inner
    response = get_response(request)
  File "/Users/chengyinliu/anaconda3/lib/python3.7/site-packages/django/core/handlers/base.py", line 113, in _get_response
    resolver_match = resolver.resolve(request.path_info)
  File "/Users/chengyinliu/anaconda3/lib/python3.7/site-packages/django/urls/resolvers.py", line 527, in resolve
    raise Resolver404({'tried': tried, 'path': new_path})
django.urls.exceptions.Resolver404: {'tried': [[<URLResolver <URLPattern list> (admin:admin) 'admin/'>], [<URLResolver <module 'backend.version_1_0' from '/Users/chengyinliu/WeChatProjects/backend/backend/version_1_0.py'> (None:None) 'api/v1.0/'>]], 'path': 'all/rss/'}

During handling of the above exception, another exception occurred:

Traceback (most recent call last):
  File "/Users/chengyinliu/anaconda3/lib/python3.7/site-packages/django/template/base.py", line 835, in _resolve_lookup
    current = current[bit]
TypeError: 'URLResolver' object is not subscriptable

During handling of the above exception, another exception occurred:

Traceback (most recent call last):
  File "/Users/chengyinliu/anaconda3/lib/python3.7/site-packages/django/template/base.py", line 843, in _resolve_lookup
    current = getattr(current, bit)
AttributeError: 'URLResolver' object has no attribute 'name'

During handling of the above exception, another exception occurred:

Traceback (most recent call last):
  File "/Users/chengyinliu/anaconda3/lib/python3.7/site-packages/django/template/base.py", line 849, in _resolve_lookup
    current = current[int(bit)]
ValueError: invalid literal for int() with base 10: 'name'

During handling of the above exception, another exception occurred:

Traceback (most recent call last):
  File "/Users/chengyinliu/anaconda3/lib/python3.7/site-packages/django/template/base.py", line 856, in _resolve_lookup
    (bit, current))  # missing attribute
django.template.base.VariableDoesNotExist: Failed lookup for key [name] in <URLResolver <URLPattern list> (admin:admin) 'admin/'>
2019-10-08 17:02:20,676 [Thread-2: 123145412268032]/Users/chengyinliu/anaconda3/lib/python3.7/site-packages/django/template/base.py:_resolve_lookup:878 DEBUG - Exception while resolving variable 'name' in template 'unknown'.
Traceback (most recent call last):
  File "/Users/chengyinliu/anaconda3/lib/python3.7/site-packages/django/core/handlers/exception.py", line 35, in inner
    response = get_response(request)
  File "/Users/chengyinliu/anaconda3/lib/python3.7/site-packages/django/core/handlers/base.py", line 113, in _get_response
    resolver_match = resolver.resolve(request.path_info)
  File "/Users/chengyinliu/anaconda3/lib/python3.7/site-packages/django/urls/resolvers.py", line 527, in resolve
    raise Resolver404({'tried': tried, 'path': new_path})
django.urls.exceptions.Resolver404: {'tried': [[<URLResolver <URLPattern list> (admin:admin) 'admin/'>], [<URLResolver <module 'backend.version_1_0' from '/Users/chengyinliu/WeChatProjects/backend/backend/version_1_0.py'> (None:None) 'api/v1.0/'>]], 'path': 'all/rss/'}

During handling of the above exception, another exception occurred:

Traceback (most recent call last):
  File "/Users/chengyinliu/anaconda3/lib/python3.7/site-packages/django/template/base.py", line 835, in _resolve_lookup
    current = current[bit]
TypeError: 'URLResolver' object is not subscriptable

During handling of the above exception, another exception occurred:

Traceback (most recent call last):
  File "/Users/chengyinliu/anaconda3/lib/python3.7/site-packages/django/template/base.py", line 843, in _resolve_lookup
    current = getattr(current, bit)
AttributeError: 'URLResolver' object has no attribute 'name'

During handling of the above exception, another exception occurred:

Traceback (most recent call last):
  File "/Users/chengyinliu/anaconda3/lib/python3.7/site-packages/django/template/base.py", line 849, in _resolve_lookup
    current = current[int(bit)]
ValueError: invalid literal for int() with base 10: 'name'

During handling of the above exception, another exception occurred:

Traceback (most recent call last):
  File "/Users/chengyinliu/anaconda3/lib/python3.7/site-packages/django/template/base.py", line 856, in _resolve_lookup
    (bit, current))  # missing attribute
django.template.base.VariableDoesNotExist: Failed lookup for key [name] in <URLResolver <module 'backend.version_1_0' from '/Users/chengyinliu/WeChatProjects/backend/backend/version_1_0.py'> (None:None) 'api/v1.0/'>
2019-10-08 17:02:20,676 [Thread-2: 123145412268032]/Users/chengyinliu/anaconda3/lib/python3.7/site-packages/django/core/handlers/base.py:get_response:93 WARNING - Not Found: /all/rss/
2019-10-08 17:02:20,677 [Thread-2: 123145412268032]/Users/chengyinliu/anaconda3/lib/python3.7/site-packages/django/core/servers/basehttp.py:log_message:124 WARNING - "GET /all/rss/ HTTP/1.1" 404 2073
2019-10-08 17:11:56,418 [Dummy-1: 123145563967488]/Users/chengyinliu/anaconda3/lib/python3.7/site-packages/django/db/backends/utils.py:execute:111 DEBUG - (0.000) SELECT @@SQL_AUTO_IS_NULL; args=None
2019-10-08 17:11:56,419 [Dummy-1: 123145563967488]/Users/chengyinliu/anaconda3/lib/python3.7/site-packages/django/db/backends/utils.py:execute:111 DEBUG - (0.000) SET SESSION TRANSACTION ISOLATION LEVEL READ COMMITTED; args=None
2019-10-08 17:11:56,419 [Dummy-1: 123145563967488]/Users/chengyinliu/anaconda3/lib/python3.7/site-packages/django/db/backends/utils.py:execute:111 DEBUG - (0.000) SELECT VERSION(); args=None
2019-10-08 17:11:56,436 [Dummy-1: 123145563967488]/Users/chengyinliu/anaconda3/lib/python3.7/site-packages/django/db/backends/utils.py:execute:111 DEBUG - (0.000) SET SESSION TRANSACTION ISOLATION LEVEL READ COMMITTED; args=None
2019-10-08 17:11:56,437 [Dummy-1: 123145563967488]/Users/chengyinliu/anaconda3/lib/python3.7/site-packages/django/db/backends/utils.py:execute:111 DEBUG - (0.001) SHOW FULL TABLES; args=None
2019-10-08 17:11:56,439 [Dummy-1: 123145563967488]/Users/chengyinliu/anaconda3/lib/python3.7/site-packages/django/db/backends/utils.py:execute:111 DEBUG - (0.001) SELECT `django_migrations`.`app`, `django_migrations`.`name` FROM `django_migrations`; args=()
2019-10-08 17:11:56,443 [Dummy-1: 123145563967488]/Users/chengyinliu/WeChatProjects/backend/module/middleware.py:__init__:14 INFO - Build StatisticsMiddleware.
2019-10-08 17:12:17,487 [Dummy-1: 123145314390016]/Users/chengyinliu/anaconda3/lib/python3.7/site-packages/django/db/backends/utils.py:execute:111 DEBUG - (0.000) SELECT @@SQL_AUTO_IS_NULL; args=None
2019-10-08 17:12:17,488 [Dummy-1: 123145314390016]/Users/chengyinliu/anaconda3/lib/python3.7/site-packages/django/db/backends/utils.py:execute:111 DEBUG - (0.000) SET SESSION TRANSACTION ISOLATION LEVEL READ COMMITTED; args=None
2019-10-08 17:12:17,488 [Dummy-1: 123145314390016]/Users/chengyinliu/anaconda3/lib/python3.7/site-packages/django/db/backends/utils.py:execute:111 DEBUG - (0.000) SELECT VERSION(); args=None
2019-10-08 17:12:17,506 [Dummy-1: 123145314390016]/Users/chengyinliu/anaconda3/lib/python3.7/site-packages/django/db/backends/utils.py:execute:111 DEBUG - (0.000) SET SESSION TRANSACTION ISOLATION LEVEL READ COMMITTED; args=None
2019-10-08 17:12:17,507 [Dummy-1: 123145314390016]/Users/chengyinliu/anaconda3/lib/python3.7/site-packages/django/db/backends/utils.py:execute:111 DEBUG - (0.001) SHOW FULL TABLES; args=None
2019-10-08 17:12:17,509 [Dummy-1: 123145314390016]/Users/chengyinliu/anaconda3/lib/python3.7/site-packages/django/db/backends/utils.py:execute:111 DEBUG - (0.001) SELECT `django_migrations`.`app`, `django_migrations`.`name` FROM `django_migrations`; args=()
2019-10-08 17:12:17,513 [Dummy-1: 123145314390016]/Users/chengyinliu/WeChatProjects/backend/module/middleware.py:__init__:14 INFO - Build StatisticsMiddleware.
2019-10-08 17:12:20,692 [Thread-2: 123145319645184]/Users/chengyinliu/anaconda3/lib/python3.7/site-packages/django/template/base.py:_resolve_lookup:878 DEBUG - Exception while resolving variable 'name' in template 'unknown'.
Traceback (most recent call last):
  File "/Users/chengyinliu/anaconda3/lib/python3.7/site-packages/django/core/handlers/exception.py", line 35, in inner
    response = get_response(request)
  File "/Users/chengyinliu/anaconda3/lib/python3.7/site-packages/django/core/handlers/base.py", line 113, in _get_response
    resolver_match = resolver.resolve(request.path_info)
  File "/Users/chengyinliu/anaconda3/lib/python3.7/site-packages/django/urls/resolvers.py", line 527, in resolve
    raise Resolver404({'tried': tried, 'path': new_path})
django.urls.exceptions.Resolver404: {'tried': [[<URLResolver <URLPattern list> (admin:admin) 'admin/'>], [<URLResolver <module 'backend.version_1_0' from '/Users/chengyinliu/WeChatProjects/backend/backend/version_1_0.py'> (None:None) 'api/v1.0/'>]], 'path': 'all/rss/'}

During handling of the above exception, another exception occurred:

Traceback (most recent call last):
  File "/Users/chengyinliu/anaconda3/lib/python3.7/site-packages/django/template/base.py", line 835, in _resolve_lookup
    current = current[bit]
TypeError: 'URLResolver' object is not subscriptable

During handling of the above exception, another exception occurred:

Traceback (most recent call last):
  File "/Users/chengyinliu/anaconda3/lib/python3.7/site-packages/django/template/base.py", line 843, in _resolve_lookup
    current = getattr(current, bit)
AttributeError: 'URLResolver' object has no attribute 'name'

During handling of the above exception, another exception occurred:

Traceback (most recent call last):
  File "/Users/chengyinliu/anaconda3/lib/python3.7/site-packages/django/template/base.py", line 849, in _resolve_lookup
    current = current[int(bit)]
ValueError: invalid literal for int() with base 10: 'name'

During handling of the above exception, another exception occurred:

Traceback (most recent call last):
  File "/Users/chengyinliu/anaconda3/lib/python3.7/site-packages/django/template/base.py", line 856, in _resolve_lookup
    (bit, current))  # missing attribute
django.template.base.VariableDoesNotExist: Failed lookup for key [name] in <URLResolver <URLPattern list> (admin:admin) 'admin/'>
2019-10-08 17:12:20,693 [Thread-2: 123145319645184]/Users/chengyinliu/anaconda3/lib/python3.7/site-packages/django/template/base.py:_resolve_lookup:878 DEBUG - Exception while resolving variable 'name' in template 'unknown'.
Traceback (most recent call last):
  File "/Users/chengyinliu/anaconda3/lib/python3.7/site-packages/django/core/handlers/exception.py", line 35, in inner
    response = get_response(request)
  File "/Users/chengyinliu/anaconda3/lib/python3.7/site-packages/django/core/handlers/base.py", line 113, in _get_response
    resolver_match = resolver.resolve(request.path_info)
  File "/Users/chengyinliu/anaconda3/lib/python3.7/site-packages/django/urls/resolvers.py", line 527, in resolve
    raise Resolver404({'tried': tried, 'path': new_path})
django.urls.exceptions.Resolver404: {'tried': [[<URLResolver <URLPattern list> (admin:admin) 'admin/'>], [<URLResolver <module 'backend.version_1_0' from '/Users/chengyinliu/WeChatProjects/backend/backend/version_1_0.py'> (None:None) 'api/v1.0/'>]], 'path': 'all/rss/'}

During handling of the above exception, another exception occurred:

Traceback (most recent call last):
  File "/Users/chengyinliu/anaconda3/lib/python3.7/site-packages/django/template/base.py", line 835, in _resolve_lookup
    current = current[bit]
TypeError: 'URLResolver' object is not subscriptable

During handling of the above exception, another exception occurred:

Traceback (most recent call last):
  File "/Users/chengyinliu/anaconda3/lib/python3.7/site-packages/django/template/base.py", line 843, in _resolve_lookup
    current = getattr(current, bit)
AttributeError: 'URLResolver' object has no attribute 'name'

During handling of the above exception, another exception occurred:

Traceback (most recent call last):
  File "/Users/chengyinliu/anaconda3/lib/python3.7/site-packages/django/template/base.py", line 849, in _resolve_lookup
    current = current[int(bit)]
ValueError: invalid literal for int() with base 10: 'name'

During handling of the above exception, another exception occurred:

Traceback (most recent call last):
  File "/Users/chengyinliu/anaconda3/lib/python3.7/site-packages/django/template/base.py", line 856, in _resolve_lookup
    (bit, current))  # missing attribute
django.template.base.VariableDoesNotExist: Failed lookup for key [name] in <URLResolver <module 'backend.version_1_0' from '/Users/chengyinliu/WeChatProjects/backend/backend/version_1_0.py'> (None:None) 'api/v1.0/'>
2019-10-08 17:12:20,694 [Thread-2: 123145319645184]/Users/chengyinliu/anaconda3/lib/python3.7/site-packages/django/core/handlers/base.py:get_response:93 WARNING - Not Found: /all/rss/
2019-10-08 17:12:20,694 [Thread-2: 123145319645184]/Users/chengyinliu/anaconda3/lib/python3.7/site-packages/django/core/servers/basehttp.py:log_message:124 WARNING - "GET /all/rss/ HTTP/1.1" 404 2073
